<?xml version="1.0" ?>
<robot name="MYROBOT" xmlns:xacro="http://www.ros.org/wiki/xacro">

    <link name="box_link">

        <inertial>
            <mass value="5"/>
            <inertia ixx="0.1" ixy="0.0" ixz="0.0" iyy="0.1" iyz="0.0" izz="0.1"/>
        </inertial>

        <collision>
            <geometry>
                <cylinder radius="0.2" length="0.3"/>
            </geometry> 
        </collision>

        <visual>
            <origin rpy="0 0 0" xyz="0 0 0"/>
            <geometry>
                <cylinder radius="0.2" length="0.3"/>
                <material name="green"/>
            </geometry>
        </visual>
    </link>

    <gazebo reference="box_link">
    	<material>Gazebo/Green</material>
    </gazebo>


    <link name="head">
        <inertial>
            <mass value="1.5"/>
            <inertia ixx="0.0" ixy="0.0" ixz="0.0" iyy="0.0" iyz="0.0" izz="0.0"/>
        </inertial>

        <collision>
            <geometry>
                <sphere radius="0.2"/>
            </geometry> 
        </collision>

        <visual>
            <origin rpy="0 0 0" xyz="0 0 0"/>
            <geometry>
                <sphere radius="0.2"/>
                <material name="blue"/>
            </geometry>
        </visual>

    </link>
    
    <gazebo reference="head">
    	<material>Gazebo/Blue</material>
    </gazebo>

    <joint name="box_head" type="fixed">
        <axis rpy="0 0 0" xyz="-1.0 0.0 0.0"/>
        <parent link="box_link"/>
        <child link="head"/>
        <origin rpy="0 0 0" xyz="0 0 0.17"/>
        <limit effort="10000" velocity="0"/>
        <joint_properties damping="1.0" friction="1.0"/>
    </joint>


    <link name="right_front_wheel">
        <visual>
            <origin rpy="1.57075 0 1.57075" xyz="0 0 0"/>
            <geometry>
                <cylinder length="0.05" radius="0.05"/>
            </geometry>
            <material name="black"/>
        </visual>

        <collision>
            <origin rpy="1.57075 0 1.57075" xyz="0 0 0"/>
            <geometry>
                <cylinder length="0.05" radius="0.05"/>
            </geometry> 
        </collision>

        <inertial>
            <mass value="1"/>
            <inertia ixx="0.03" ixy="0" ixz="0" iyy="0.1" iyz="0" izz="0.1"/>
        </inertial>

    </link>

    <gazebo reference="right_front_wheel">
    	<material>Gazebo/Black</material>
    </gazebo>

    <joint name="box_right_front_wheel" type="continuous">
        <axis rpy="0 0 0" xyz="-1.0 0.0 0.0"/>
        <parent link="box_link"/>
        <child link="right_front_wheel"/>
        <origin rpy="0 0 0" xyz="0.15 0.1 -0.2"/>
        <limit effort="10000" velocity="1000"/>
        <joint_properties damping="1.0" friction="1.0"/>
    </joint>

    <link name="right_back_wheel">
        <visual>
            <origin rpy="1.57075 0 1.57075" xyz="0 0 0"/>
            <geometry>
                <cylinder length="0.05" radius="0.05"/>
            </geometry>
            <material name="black"/>
        </visual>

        <collision>
            <origin rpy="1.57075 0 1.57075" xyz="0 0 0"/>
            <geometry>
                <cylinder length="0.05" radius="0.05"/>
            </geometry> 
        </collision>

        <inertial>
            <mass value="1"/>
            <inertia ixx="0.03" ixy="0" ixz="0" iyy="0.1" iyz="0" izz="0.1"/>
        </inertial>

    </link>

    <gazebo reference="right_back_wheel">
    	<material>Gazebo/Black</material>
    </gazebo>

    <joint name="box_right_back_wheel" type="continuous">
        <axis rpy="0 0 0" xyz="-1.0 0.0 0.0"/>
        <parent link="box_link"/>
        <child link="right_back_wheel"/>
        <origin rpy="0 0 0" xyz="0.15 -0.1 -0.2"/>
        <limit effort="10000" velocity="1000"/>
        <joint_properties damping="1.0" friction="1.0"/>
    </joint>


    <link name="left_front_wheel">
        <visual>
            <origin rpy="-1.57075 0 1.57075" xyz="0 0 0"/>
            <geometry>
                <cylinder length="0.05" radius="0.05"/>
            </geometry>
            <material name="black"/>
        </visual>

        <collision>
            <origin rpy="-1.57075 0 1.57075" xyz="0 0 0"/>
            <geometry>
                <cylinder length="0.05" radius="0.05"/>
            </geometry> 
        </collision>

        <inertial>
            <mass value="1"/>
            <inertia ixx="0.03" ixy="0" ixz="0" iyy="0.1" iyz="0" izz="0.1"/>
        </inertial>

    </link>

    <gazebo reference="left_front_wheel">
    	<material>Gazebo/Black</material>
    </gazebo>

    <joint name="box_left_front_wheel" type="continuous">
        <axis rpy="0 0 0" xyz="-1.0 0.0 0.0"/>
        <parent link="box_link"/>
        <child link="left_front_wheel"/>
        <origin rpy="0 0 0" xyz="-0.15 0.1 -0.2"/>
        <limit effort="10000" velocity="1000"/>
        <joint_properties damping="1.0" friction="1.0"/>
    </joint>

    <link name="left_back_wheel">
        <visual>
            <origin rpy="-1.57075 0 1.57075" xyz="0 0 0"/>
            <geometry>
                <cylinder length="0.05" radius="0.05"/>
            </geometry>
            <material name="black"/>
        </visual>

        <collision>
            <origin rpy="-1.57075 0 1.57075" xyz="0 0 0"/>
            <geometry>
                <cylinder length="0.05" radius="0.05"/>
            </geometry> 
        </collision>

        <inertial>
            <mass value="1"/>
            <inertia ixx="0.03" ixy="0" ixz="0" iyy="0.1" iyz="0" izz="0.1"/>
        </inertial>

    </link>

    <gazebo reference="left_back_wheel">
    	<material>Gazebo/Black</material>
    </gazebo>

    <joint name="box_left_wheel" type="continuous">
        <axis rpy="0 0 0" xyz="-1.0 0.0 0.0"/>
        <parent link="box_link"/>
        <child link="left_back_wheel"/>
        <origin rpy="0 0 0" xyz="-0.15 -0.1 -0.2"/>
        <limit effort="10000" velocity="1000"/>
        <joint_properties damping="1.0" friction="1.0"/>
    </joint>    

    <link name="right_eye">

        <inertial>
            <mass value="0.001"/>
            <inertia ixx="0.1" ixy="0.0" ixz="0.0" iyy="0.1" iyz="0.0" izz="0.1"/>
        </inertial>

        <collision>
            <geometry>
                <cylinder radius="0.02" length="0.01"/>
            </geometry> 
        </collision>

        <visual>
            <origin rpy="-1.57075 1.57075 0" xyz="0 0 0"/>
            <geometry>
                <cylinder radius="0.02" length="0.01"/>
                <material name="black"/>
            </geometry>
        </visual>
    </link>

    <gazebo reference="right_eye">
    	<material>Gazebo/Black</material>
    </gazebo>

    <joint name="head_right_eye" type="fixed">
        <axis rpy="0 0 0" xyz="-1.0 0.0 0.0"/>
        <parent link="head"/>
        <child link="right_eye"/>
        <origin rpy="0 -0.3 0" xyz="0.07 0.19 0.05"/>
        <limit effort="10000" velocity="0"/>
        <joint_properties damping="1.0" friction="1.0"/>
    </joint>

    <link name="left_eye">

        <inertial>
            <mass value="0.001"/>
            <inertia ixx="0.1" ixy="0.0" ixz="0.0" iyy="0.1" iyz="0.0" izz="0.1"/>
        </inertial>

        <collision>
            <geometry>
                <cylinder radius="0.02" length="0.01"/>
            </geometry> 
        </collision>

        <visual>
            <origin rpy="-1.57075 1.57075 0" xyz="0 0 0"/>
            <geometry>
                <cylinder radius="0.02" length="0.01"/>
                <material name="black"/>
            </geometry>
        </visual>
    </link>

    <gazebo reference="left_eye">
    	<material>Gazebo/Black</material>
    </gazebo>

    <joint name="head_left_eye" type="fixed">
        <axis rpy="0 0 0" xyz="-1.0 0.0 0.0"/>
        <parent link="head"/>
        <child link="left_eye"/>
        <origin rpy="0 -0.3 0" xyz="-0.07 0.19 0.05"/>
        <limit effort="10000" velocity="0"/>
        <joint_properties damping="1.0" friction="1.0"/>
    </joint>

</robot>